Workbook
Name Slicer_BusinessTravel: #N/A
Name Slicer_Department: #N/A
Name Slicer_Gender: #N/A
Name Slicer_JobRole: #N/A

Sheet Raw_data
A1: Age | B1: Attrition | C1: BusinessTravel | D1: DailyRate | E1: Department | F1: DistanceFromHome | G1: Education | H1: EducationField | I1: EmployeeCount | J1: EmployeeNumber | K1: EnvironmentSatisfaction | L1: Gender | M1: HourlyRate | N1: JobInvolvement | O1: JobLevel | P1: JobRole | Q1: JobSatisfaction | R1: MaritalStatus | S1: MonthlyIncome | T1: MonthlyRate | U1: NumCompaniesWorked | V1: Over18 | W1: OverTime | X1: PercentSalaryHike | Y1: PerformanceRating | Z1: RelationshipSatisfaction | AA1: StandardHours | AB1: StockOptionLevel | AC1: TotalWorkingYears | AD1: TrainingTimesLastYear | AE1: WorkLifeBalance | AF1: YearsAtCompany | AG1: YearsInCurrentRole | AH1: YearsSinceLastPromotion | AI1: YearsWithCurrManager
A2: 41 | B2: Yes | C2: Travel_Rarely | D2: 1102 | E2: Sales | F2: 1 | G2: 2 | H2: Life Sciences | I2: 1 | J2: 1 | K2: 2 | L2: Female | M2: 94 | N2: 3 | O2: 2 | P2: Sales Executive | Q2: 4 | R2: Single | S2: 5993 | T2: 19479 | U2: 8 | V2: Y | W2: Yes | X2: 11 | Y2: 3 | Z2: 1 | AA2: 80 | AB2: 0 | AC2: 8 | AD2: 0 | AE2: 1 | AF2: 6 | AG2: 4 | AH2: 0 | AI2: 5
A3: 49 | B3: No | C3: Travel_Frequently | D3: 279 | E3: Research & Development | F3: 8 | G3: 1 | H3: Life Sciences | I3: 1 | J3: 2 | K3: 3 | L3: Male | M3: 61 | N3: 2 | O3: 2 | P3: Research Scientist | Q3: 2 | R3: Married | S3: 5130 | T3: 24907 | U3: 1 | V3: Y | W3: No | X3: 23 | Y3: 4 | Z3: 4 | AA3: 80 | AB3: 1 | AC3: 10 | AD3: 3 | AE3: 3 | AF3: 10 | AG3: 7 | AH3: 1 | AI3: 7
A4: 37 | B4: Yes | C4: Travel_Rarely | D4: 1373 | E4: Research & Development | F4: 2 | G4: 2 | H4: Other | I4: 1 | J4: 4 | K4: 4 | L4: Male | M4: 92 | N4: 2 | O4: 1 | P4: Laboratory Technician | Q4: 3 | R4: Single | S4: 2090 | T4: 2396 | U4: 6 | V4: Y | W4: Yes | X4: 15 | Y4: 3 | Z4: 2 | AA4: 80 | AB4: 0 | AC4: 7 | AD4: 3 | AE4: 3 | AF4: 0 | AG4: 0 | AH4: 0 | AI4: 0
A5: 33 | B5: No | C5: Travel_Frequently | D5: 1392 | E5: Research & Development | F5: 3 | G5: 4 | H5: Life Sciences | I5: 1 | J5: 5 | K5: 4 | L5: Female | M5: 56 | N5: 3 | O5: 1 | P5: Research Scientist | Q5: 3 | R5: Married | S5: 2909 | T5: 23159 | U5: 1 | V5: Y | W5: Yes | X5: 11 | Y5: 3 | Z5: 3 | AA5: 80 | AB5: 0 | AC5: 8 | AD5: 3 | AE5: 3 | AF5: 8 | AG5: 7 | AH5: 3 | AI5: 0
A6: 27 | B6: No | C6: Travel_Rarely | D6: 591 | E6: Research & Development | F6: 2 | G6: 1 | H6: Medical | I6: 1 | J6: 7 | K6: 1 | L6: Male | M6: 40 | N6: 3 | O6: 1 | P6: Laboratory Technician | Q6: 2 | R6: Married | S6: 3468 | T6: 16632 | U6: 9 | V6: Y | W6: No | X6: 12 | Y6: 3 | Z6: 4 | AA6: 80 | AB6: 1 | AC6: 6 | AD6: 3 | AE6: 3 | AF6: 2 | AG6: 2 | AH6: 2 | AI6: 2
A7: 32 | B7: No | C7: Travel_Frequently | D7: 1005 | E7: Research & Development | F7: 2 | G7: 2 | H7: Life Sciences | I7: 1 | J7: 8 | K7: 4 | L7: Male | M7: 79 | N7: 3 | O7: 1 | P7: Laboratory Technician | Q7: 4 | R7: Single | S7: 3068 | T7: 11864 | U7: 0 | V7: Y | W7: No | X7: 13 | Y7: 3 | Z7: 3 | AA7: 80 | AB7: 0 | AC7: 8 | AD7: 2 | AE7: 2 | AF7: 7 | AG7: 7 | AH7: 3 | AI7: 6
A8: 59 | B8: No | C8: Travel_Rarely | D8: 1324 | E8: Research & Development | F8: 3 | G8: 3 | H8: Medical | I8: 1 | J8: 10 | K8: 3 | L8: Female | M8: 81 | N8: 4 | O8: 1 | P8: Laboratory Technician | Q8: 1 | R8: Married | S8: 2670 | T8: 9964 | U8: 4 | V8: Y | W8: Yes | X8: 20 | Y8: 4 | Z8: 1 | AA8: 80 | AB8: 3 | AC8: 12 | AD8: 3 | AE8: 2 | AF8: 1 | AG8: 0 | AH8: 0 | AI8: 0
A9: 30 | B9: No | C9: Travel_Rarely | D9: 1358 | E9: Research & Development | F9: 24 | G9: 1 | H9: Life Sciences | I9: 1 | J9: 11 | K9: 4 | L9: Male | M9: 67 | N9: 3 | O9: 1 | P9: Laboratory Technician | Q9: 3 | R9: Divorced | S9: 2693 | T9: 13335 | U9: 1 | V9: Y | W9: No | X9: 22 | Y9: 4 | Z9: 2 | AA9: 80 | AB9: 1 | AC9: 1 | AD9: 2 | AE9: 3 | AF9: 1 | AG9: 0 | AH9: 0 | AI9: 0
A10: 38 | B10: No | C10: Travel_Frequently | D10: 216 | E10: Research & Development | F10: 23 | G10: 3 | H10: Life Sciences | I10: 1 | J10: 12 | K10: 4 | L10: Male | M10: 44 | N10: 2 | O10: 3 | P10: Manufacturing Director | Q10: 3 | R10: Single | S10: 9526 | T10: 8787 | U10: 0 | V10: Y | W10: No | X10: 21 | Y10: 4 | Z10: 2 | AA10: 80 | AB10: 0 | AC10: 10 | AD10: 2 | AE10: 3 | AF10: 9 | AG10: 7 | AH10: 1 | AI10: 8
A11: 36 | B11: No | C11: Travel_Rarely | D11: 1299 | E11: Research & Development | F11: 27 | G11: 3 | H11: Medical | I11: 1 | J11: 13 | K11: 3 | L11: Male | M11: 94 | N11: 3 | O11: 2 | P11: Healthcare Representative | Q11: 3 | R11: Married | S11: 5237 | T11: 16577 | U11: 6 | V11: Y | W11: No | X11: 13 | Y11: 3 | Z11: 2 | AA11: 80 | AB11: 2 | AC11: 17 | AD11: 3 | AE11: 2 | AF11: 7 | AG11: 7 | AH11: 7 | AI11: 7
A12: 35 | B12: No | C12: Travel_Rarely | D12: 809 | E12: Research & Development | F12: 16 | G12: 3 | H12: Medical | I12: 1 | J12: 14 | K12: 1 | L12: Male | M12: 84 | N12: 4 | O12: 1 | P12: Laboratory Technician | Q12: 2 | R12: Married | S12: 2426 | T12: 16479 | U12: 0 | V12: Y | W12: No | X12: 13 | Y12: 3 | Z12: 3 | AA12: 80 | AB12: 1 | AC12: 6 | AD12: 5 | AE12: 3 | AF12: 5 | AG12: 4 | AH12: 0 | AI12: 3
A13: 29 | B13: No | C13: Travel_Rarely | D13: 153 | E13: Research & Development | F13: 15 | G13: 2 | H13: Life Sciences | I13: 1 | J13: 15 | K13: 4 | L13: Female | M13: 49 | N13: 2 | O13: 2 | P13: Laboratory Technician | Q13: 3 | R13: Single | S13: 4193 | T13: 12682 | U13: 0 | V13: Y | W13: Yes | X13: 12 | Y13: 3 | Z13: 4 | AA13: 80 | AB13: 0 | AC13: 10 | AD13: 3 | AE13: 3 | AF13: 9 | AG13: 5 | AH13: 0 | AI13: 8
... A1471: 34 | B1471: No | C1471: Travel_Rarely | D1471: 628 | E1471: Research & Development | F1471: 8 | G1471: 3 | H1471: Medical | I1471: 1 | J1471: 2068 | K1471: 2 | L1471: Male | M1471: 82 | N1471: 4 | O1471: 2 | P1471: Laboratory Technician | Q1471: 3 | R1471: Married | S1471: 4404 | T1471: 10228 | U1471: 2 | V1471: Y | W1471: No | X1471: 12 | Y1471: 3 | Z1471: 1 | AA1471: 80 | AB1471: 0 | AC1471: 6 | AD1471: 3 | AE1471: 4 | AF1471: 4 | AG1471: 3 | AH1471: 1 | AI1471: 2

Sheet Clean_data
A1: Age | B1: CategoryAge | C1: Attrition | D1: Attrition Flag | E1: BusinessTravel | F1: DailyRate | G1: Department | H1: DistanceFromHome | I1: CategoryDistance | J1: Education | K1: EducationField | L1: EmployeeNumber | M1: EnvironmentSatisfaction | N1: Gender | O1: HourlyRate | P1: JobInvolvement | Q1: JobLevel | R1: JobRole | S1: JobSatisfaction | T1: CategoryJobSatisfaction | U1: MaritalStatus | V1: MonthlyIncome | W1: CategoryMonthlyIncome | X1: MonthlyRate | Y1: NumCompaniesWorked | Z1: OverTime | AA1: PercentSalaryHike | AB1: PerformanceRating | AC1: RelationshipSatisfaction | AD1: StockOptionLevel | AE1: TotalWorkingYears | AF1: TrainingTimesLastYear | AG1: WorkLifeBalance | AH1: YearsAtCompany | AI1: CategoryYearsatCompany | AJ1: YearsInCurrentRole | AK1: YearsSinceLastPromotion | AL1: YearsWithCurrManager
A2: 41 | B2: {=_xlfn.IFS(A2<25,"<25",A2<=34,"25-34",A2<=44,"35-44",A2<=54,"45-54",A2>=55,"55++")} -> 35-44 | C2: Yes | D2: =IF(C2="Yes",1,0) -> 1 | E2: Travel_Rarely | F2: 1102 | G2: Sales | H2: 1 | I2: {=_xlfn.IFS(H2<=5,"0-5 km",H2<=10,"6-10 km",H2<=20,"11-20 km",H2>20,"20 km+")} -> 0-5 km | J2: 2 | K2: Life Sciences | L2: 1 | M2: 2 | N2: Female | O2: 94 | P2: 3 | Q2: 2 | R2: Sales Executive | S2: 4 | T2: {=_xlfn.IFS(S2=1,"Low",S2=2,"Medium",S2=3,"High",S2=4,"Very High")} -> Very High | U2: Single | V2: 5993 | W2: {=_xlfn.IFS(V2<=$AQ$3,"Low",V2<=$AQ$4,"Lower Middle",V2<=$AQ$5,"Upper Middle",V2>$AQ$5,"High")} -> Upper Middle | X2: 19479 | Y2: 8 | Z2: Yes | AA2: 11 | AB2: 3 | AC2: 1 | AD2: 0 | AE2: 8 | AF2: 0 | AG2: 1 | AH2: 6 | AI2: {=_xlfn.IFS(AH2<2,"<2 Years",AH2<=5, "2-5 Years",AH2<=10,"6-10 Years",AH2>10,"10++ Years")} -> 6-10 Years | AJ2: 4 | AK2: 0 | AL2: 5 | AQ2: Quartile Monthly Income
A3: 49 | B3: {=_xlfn.IFS(A3<25,"<25",A3<=34,"25-34",A3<=44,"35-44",A3<=54,"45-54",A3>=55,"55++")} -> 45-54 | C3: No | D3: =IF(C3="Yes",1,0) -> 0 | E3: Travel_Frequently | F3: 279 | G3: Research & Development | H3: 8 | I3: {=_xlfn.IFS(H3<=5,"0-5 km",H3<=10,"6-10 km",H3<=20,"11-20 km",H3>20,"20 km+")} -> 6-10 km | J3: 1 | K3: Life Sciences | L3: 2 | M3: 3 | N3: Male | O3: 61 | P3: 2 | Q3: 2 | R3: Research Scientist | S3: 2 | T3: {=_xlfn.IFS(S3=1,"Low",S3=2,"Medium",S3=3,"High",S3=4,"Very High")} -> Medium | U3: Married | V3: 5130 | W3: {=_xlfn.IFS(V3<=$AQ$3,"Low",V3<=$AQ$4,"Lower Middle",V3<=$AQ$5,"Upper Middle",V3>$AQ$5,"High")} -> Upper Middle | X3: 24907 | Y3: 1 | Z3: No | AA3: 23 | AB3: 4 | AC3: 4 | AD3: 1 | AE3: 10 | AF3: 3 | AG3: 3 | AH3: 10 | AI3: {=_xlfn.IFS(AH3<2,"<2 Years",AH3<=5, "2-5 Years",AH3<=10,"6-10 Years",AH3>10,"10++ Years")} -> 6-10 Years | AJ3: 7 | AK3: 1 | AL3: 7 | AQ3: =_xlfn.QUARTILE.INC(V:V,1) -> 2911
A4: 37 | B4: {=_xlfn.IFS(A4<25,"<25",A4<=34,"25-34",A4<=44,"35-44",A4<=54,"45-54",A4>=55,"55++")} -> 35-44 | C4: Yes | D4: =IF(C4="Yes",1,0) -> 1 | E4: Travel_Rarely | F4: 1373 | G4: Research & Development | H4: 2 | I4: {=_xlfn.IFS(H4<=5,"0-5 km",H4<=10,"6-10 km",H4<=20,"11-20 km",H4>20,"20 km+")} -> 0-5 km | J4: 2 | K4: Other | L4: 4 | M4: 4 | N4: Male | O4: 92 | P4: 2 | Q4: 1 | R4: Laboratory Technician | S4: 3 | T4: {=_xlfn.IFS(S4=1,"Low",S4=2,"Medium",S4=3,"High",S4=4,"Very High")} -> High | U4: Single | V4: 2090 | W4: {=_xlfn.IFS(V4<=$AQ$3,"Low",V4<=$AQ$4,"Lower Middle",V4<=$AQ$5,"Upper Middle",V4>$AQ$5,"High")} -> Low | X4: 2396 | Y4: 6 | Z4: Yes | AA4: 15 | AB4: 3 | AC4: 2 | AD4: 0 | AE4: 7 | AF4: 3 | AG4: 3 | AH4: 0 | AI4: {=_xlfn.IFS(AH4<2,"<2 Years",AH4<=5, "2-5 Years",AH4<=10,"6-10 Years",AH4>10,"10++ Years")} -> <2 Years | AJ4: 0 | AK4: 0 | AL4: 0 | AQ4: =_xlfn.QUARTILE.INC(V:V,2) -> 4919
A5: 33 | B5: {=_xlfn.IFS(A5<25,"<25",A5<=34,"25-34",A5<=44,"35-44",A5<=54,"45-54",A5>=55,"55++")} -> 25-34 | C5: No | D5: =IF(C5="Yes",1,0) -> 0 | E5: Travel_Frequently | F5: 1392 | G5: Research & Development | H5: 3 | I5: {=_xlfn.IFS(H5<=5,"0-5 km",H5<=10,"6-10 km",H5<=20,"11-20 km",H5>20,"20 km+")} -> 0-5 km | J5: 4 | K5: Life Sciences | L5: 5 | M5: 4 | N5: Female | O5: 56 | P5: 3 | Q5: 1 | R5: Research Scientist | S5: 3 | T5: {=_xlfn.IFS(S5=1,"Low",S5=2,"Medium",S5=3,"High",S5=4,"Very High")} -> High | U5: Married | V5: 2909 | W5: {=_xlfn.IFS(V5<=$AQ$3,"Low",V5<=$AQ$4,"Lower Middle",V5<=$AQ$5,"Upper Middle",V5>$AQ$5,"High")} -> Low | X5: 23159 | Y5: 1 | Z5: Yes | AA5: 11 | AB5: 3 | AC5: 3 | AD5: 0 | AE5: 8 | AF5: 3 | AG5: 3 | AH5: 8 | AI5: {=_xlfn.IFS(AH5<2,"<2 Years",AH5<=5, "2-5 Years",AH5<=10,"6-10 Years",AH5>10,"10++ Years")} -> 6-10 Years | AJ5: 7 | AK5: 3 | AL5: 0 | AQ5: =_xlfn.QUARTILE.INC(V:V,3) -> 8379
A6: 27 | B6: {=_xlfn.IFS(A6<25,"<25",A6<=34,"25-34",A6<=44,"35-44",A6<=54,"45-54",A6>=55,"55++")} -> 25-34 | C6: No | D6: =IF(C6="Yes",1,0) -> 0 | E6: Travel_Rarely | F6: 591 | G6: Research & Development | H6: 2 | I6: {=_xlfn.IFS(H6<=5,"0-5 km",H6<=10,"6-10 km",H6<=20,"11-20 km",H6>20,"20 km+")} -> 0-5 km | J6: 1 | K6: Medical | L6: 7 | M6: 1 | N6: Male | O6: 40 | P6: 3 | Q6: 1 | R6: Laboratory Technician | S6: 2 | T6: {=_xlfn.IFS(S6=1,"Low",S6=2,"Medium",S6=3,"High",S6=4,"Very High")} -> Medium | U6: Married | V6: 3468 | W6: {=_xlfn.IFS(V6<=$AQ$3,"Low",V6<=$AQ$4,"Lower Middle",V6<=$AQ$5,"Upper Middle",V6>$AQ$5,"High")} -> Lower Middle | X6: 16632 | Y6: 9 | Z6: No | AA6: 12 | AB6: 3 | AC6: 4 | AD6: 1 | AE6: 6 | AF6: 3 | AG6: 3 | AH6: 2 | AI6: {=_xlfn.IFS(AH6<2,"<2 Years",AH6<=5, "2-5 Years",AH6<=10,"6-10 Years",AH6>10,"10++ Years")} -> 2-5 Years | AJ6: 2 | AK6: 2 | AL6: 2
A7: 32 | B7: {=_xlfn.IFS(A7<25,"<25",A7<=34,"25-34",A7<=44,"35-44",A7<=54,"45-54",A7>=55,"55++")} -> 25-34 | C7: No | D7: =IF(C7="Yes",1,0) -> 0 | E7: Travel_Frequently | F7: 1005 | G7: Research & Development | H7: 2 | I7: {=_xlfn.IFS(H7<=5,"0-5 km",H7<=10,"6-10 km",H7<=20,"11-20 km",H7>20,"20 km+")} -> 0-5 km | J7: 2 | K7: Life Sciences | L7: 8 | M7: 4 | N7: Male | O7: 79 | P7: 3 | Q7: 1 | R7: Laboratory Technician | S7: 4 | T7: {=_xlfn.IFS(S7=1,"Low",S7=2,"Medium",S7=3,"High",S7=4,"Very High")} -> Very High | U7: Single | V7: 3068 | W7: {=_xlfn.IFS(V7<=$AQ$3,"Low",V7<=$AQ$4,"Lower Middle",V7<=$AQ$5,"Upper Middle",V7>$AQ$5,"High")} -> Lower Middle | X7: 11864 | Y7: 0 | Z7: No | AA7: 13 | AB7: 3 | AC7: 3 | AD7: 0 | AE7: 8 | AF7: 2 | AG7: 2 | AH7: 7 | AI7: {=_xlfn.IFS(AH7<2,"<2 Years",AH7<=5, "2-5 Years",AH7<=10,"6-10 Years",AH7>10,"10++ Years")} -> 6-10 Years | AJ7: 7 | AK7: 3 | AL7: 6
A8: 59 | B8: {=_xlfn.IFS(A8<25,"<25",A8<=34,"25-34",A8<=44,"35-44",A8<=54,"45-54",A8>=55,"55++")} -> 55++ | C8: No | D8: =IF(C8="Yes",1,0) -> 0 | E8: Travel_Rarely | F8: 1324 | G8: Research & Development | H8: 3 | I8: {=_xlfn.IFS(H8<=5,"0-5 km",H8<=10,"6-10 km",H8<=20,"11-20 km",H8>20,"20 km+")} -> 0-5 km | J8: 3 | K8: Medical | L8: 10 | M8: 3 | N8: Female | O8: 81 | P8: 4 | Q8: 1 | R8: Laboratory Technician | S8: 1 | T8: {=_xlfn.IFS(S8=1,"Low",S8=2,"Medium",S8=3,"High",S8=4,"Very High")} -> Low | U8: Married | V8: 2670 | W8: {=_xlfn.IFS(V8<=$AQ$3,"Low",V8<=$AQ$4,"Lower Middle",V8<=$AQ$5,"Upper Middle",V8>$AQ$5,"High")} -> Low | X8: 9964 | Y8: 4 | Z8: Yes | AA8: 20 | AB8: 4 | AC8: 1 | AD8: 3 | AE8: 12 | AF8: 3 | AG8: 2 | AH8: 1 | AI8: {=_xlfn.IFS(AH8<2,"<2 Years",AH8<=5, "2-5 Years",AH8<=10,"6-10 Years",AH8>10,"10++ Years")} -> <2 Years | AJ8: 0 | AK8: 0 | AL8: 0
A9: 30 | B9: {=_xlfn.IFS(A9<25,"<25",A9<=34,"25-34",A9<=44,"35-44",A9<=54,"45-54",A9>=55,"55++")} -> 25-34 | C9: No | D9: =IF(C9="Yes",1,0) -> 0 | E9: Travel_Rarely | F9: 1358 | G9: Research & Development | H9: 24 | I9: {=_xlfn.IFS(H9<=5,"0-5 km",H9<=10,"6-10 km",H9<=20,"11-20 km",H9>20,"20 km+")} -> 20 km+ | J9: 1 | K9: Life Sciences | L9: 11 | M9: 4 | N9: Male | O9: 67 | P9: 3 | Q9: 1 | R9: Laboratory Technician | S9: 3 | T9: {=_xlfn.IFS(S9=1,"Low",S9=2,"Medium",S9=3,"High",S9=4,"Very High")} -> High | U9: Divorced | V9: 2693 | W9: {=_xlfn.IFS(V9<=$AQ$3,"Low",V9<=$AQ$4,"Lower Middle",V9<=$AQ$5,"Upper Middle",V9>$AQ$5,"High")} -> Low | X9: 13335 | Y9: 1 | Z9: No | AA9: 22 | AB9: 4 | AC9: 2 | AD9: 1 | AE9: 1 | AF9: 2 | AG9: 3 | AH9: 1 | AI9: {=_xlfn.IFS(AH9<2,"<2 Years",AH9<=5, "2-5 Years",AH9<=10,"6-10 Years",AH9>10,"10++ Years")} -> <2 Years | AJ9: 0 | AK9: 0 | AL9: 0
A10: 38 | B10: {=_xlfn.IFS(A10<25,"<25",A10<=34,"25-34",A10<=44,"35-44",A10<=54,"45-54",A10>=55,"55++")} -> 35-44 | C10: No | D10: =IF(C10="Yes",1,0) -> 0 | E10: Travel_Frequently | F10: 216 | G10: Research & Development | H10: 23 | I10: {=_xlfn.IFS(H10<=5,"0-5 km",H10<=10,"6-10 km",H10<=20,"11-20 km",H10>20,"20 km+")} -> 20 km+ | J10: 3 | K10: Life Sciences | L10: 12 | M10: 4 | N10: Male | O10: 44 | P10: 2 | Q10: 3 | R10: Manufacturing Director | S10: 3 | T10: {=_xlfn.IFS(S10=1,"Low",S10=2,"Medium",S10=3,"High",S10=4,"Very High")} -> High | U10: Single | V10: 9526 | W10: {=_xlfn.IFS(V10<=$AQ$3,"Low",V10<=$AQ$4,"Lower Middle",V10<=$AQ$5,"Upper Middle",V10>$AQ$5,"High")} -> High | X10: 8787 | Y10: 0 | Z10: No | AA10: 21 | AB10: 4 | AC10: 2 | AD10: 0 | AE10: 10 | AF10: 2 | AG10: 3 | AH10: 9 | AI10: {=_xlfn.IFS(AH10<2,"<2 Years",AH10<=5, "2-5 Years",AH10<=10,"6-10 Years",AH10>10,"10++ Years")} -> 6-10 Years | AJ10: 7 | AK10: 1 | AL10: 8
A11: 36 | B11: {=_xlfn.IFS(A11<25,"<25",A11<=34,"25-34",A11<=44,"35-44",A11<=54,"45-54",A11>=55,"55++")} -> 35-44 | C11: No | D11: =IF(C11="Yes",1,0) -> 0 | E11: Travel_Rarely | F11: 1299 | G11: Research & Development | H11: 27 | I11: {=_xlfn.IFS(H11<=5,"0-5 km",H11<=10,"6-10 km",H11<=20,"11-20 km",H11>20,"20 km+")} -> 20 km+ | J11: 3 | K11: Medical | L11: 13 | M11: 3 | N11: Male | O11: 94 | P11: 3 | Q11: 2 | R11: Healthcare Representative | S11: 3 | T11: {=_xlfn.IFS(S11=1,"Low",S11=2,"Medium",S11=3,"High",S11=4,"Very High")} -> High | U11: Married | V11: 5237 | W11: {=_xlfn.IFS(V11<=$AQ$3,"Low",V11<=$AQ$4,"Lower Middle",V11<=$AQ$5,"Upper Middle",V11>$AQ$5,"High")} -> Upper Middle | X11: 16577 | Y11: 6 | Z11: No | AA11: 13 | AB11: 3 | AC11: 2 | AD11: 2 | AE11: 17 | AF11: 3 | AG11: 2 | AH11: 7 | AI11: {=_xlfn.IFS(AH11<2,"<2 Years",AH11<=5, "2-5 Years",AH11<=10,"6-10 Years",AH11>10,"10++ Years")} -> 6-10 Years | AJ11: 7 | AK11: 7 | AL11: 7
A12: 35 | B12: {=_xlfn.IFS(A12<25,"<25",A12<=34,"25-34",A12<=44,"35-44",A12<=54,"45-54",A12>=55,"55++")} -> 35-44 | C12: No | D12: =IF(C12="Yes",1,0) -> 0 | E12: Travel_Rarely | F12: 809 | G12: Research & Development | H12: 16 | I12: {=_xlfn.IFS(H12<=5,"0-5 km",H12<=10,"6-10 km",H12<=20,"11-20 km",H12>20,"20 km+")} -> 11-20 km | J12: 3 | K12: Medical | L12: 14 | M12: 1 | N12: Male | O12: 84 | P12: 4 | Q12: 1 | R12: Laboratory Technician | S12: 2 | T12: {=_xlfn.IFS(S12=1,"Low",S12=2,"Medium",S12=3,"High",S12=4,"Very High")} -> Medium | U12: Married | V12: 2426 | W12: {=_xlfn.IFS(V12<=$AQ$3,"Low",V12<=$AQ$4,"Lower Middle",V12<=$AQ$5,"Upper Middle",V12>$AQ$5,"High")} -> Low | X12: 16479 | Y12: 0 | Z12: No | AA12: 13 | AB12: 3 | AC12: 3 | AD12: 1 | AE12: 6 | AF12: 5 | AG12: 3 | AH12: 5 | AI12: {=_xlfn.IFS(AH12<2,"<2 Years",AH12<=5, "2-5 Years",AH12<=10,"6-10 Years",AH12>10,"10++ Years")} -> 2-5 Years | AJ12: 4 | AK12: 0 | AL12: 3
A13: 29 | B13: {=_xlfn.IFS(A13<25,"<25",A13<=34,"25-34",A13<=44,"35-44",A13<=54,"45-54",A13>=55,"55++")} -> 25-34 | C13: No | D13: =IF(C13="Yes",1,0) -> 0 | E13: Travel_Rarely | F13: 153 | G13: Research & Development | H13: 15 | I13: {=_xlfn.IFS(H13<=5,"0-5 km",H13<=10,"6-10 km",H13<=20,"11-20 km",H13>20,"20 km+")} -> 11-20 km | J13: 2 | K13: Life Sciences | L13: 15 | M13: 4 | N13: Female | O13: 49 | P13: 2 | Q13: 2 | R13: Laboratory Technician | S13: 3 | T13: {=_xlfn.IFS(S13=1,"Low",S13=2,"Medium",S13=3,"High",S13=4,"Very High")} -> High | U13: Single | V13: 4193 | W13: {=_xlfn.IFS(V13<=$AQ$3,"Low",V13<=$AQ$4,"Lower Middle",V13<=$AQ$5,"Upper Middle",V13>$AQ$5,"High")} -> Lower Middle | X13: 12682 | Y13: 0 | Z13: Yes | AA13: 12 | AB13: 3 | AC13: 4 | AD13: 0 | AE13: 10 | AF13: 3 | AG13: 3 | AH13: 9 | AI13: {=_xlfn.IFS(AH13<2,"<2 Years",AH13<=5, "2-5 Years",AH13<=10,"6-10 Years",AH13>10,"10++ Years")} -> 6-10 Years | AJ13: 5 | AK13: 0 | AL13: 8
A14: 31 | B14: {=_xlfn.IFS(A14<25,"<25",A14<=34,"25-34",A14<=44,"35-44",A14<=54,"45-54",A14>=55,"55++")} -> 25-34 | C14: No | D14: =IF(C14="Yes",1,0) -> 0 | E14: Travel_Rarely | F14: 670 | G14: Research & Development | H14: 26 | I14: {=_xlfn.IFS(H14<=5,"0-5 km",H14<=10,"6-10 km",H14<=20,"11-20 km",H14>20,"20 km+")} -> 20 km+ | J14: 1 | K14: Life Sciences | L14: 16 | M14: 1 | N14: Male | O14: 31 | P14: 3 | Q14: 1 | R14: Research Scientist | S14: 3 | T14: {=_xlfn.IFS(S14=1,"Low",S14=2,"Medium",S14=3,"High",S14=4,"Very High")} -> High | U14: Divorced | V14: 2911 | W14: {=_xlfn.IFS(V14<=$AQ$3,"Low",V14<=$AQ$4,"Lower Middle",V14<=$AQ$5,"Upper Middle",V14>$AQ$5,"High")} -> Low | X14: 15170 | Y14: 1 | Z14: No | AA14: 17 | AB14: 3 | AC14: 4 | AD14: 1 | AE14: 5 | AF14: 1 | AG14: 2 | AH14: 5 | AI14: {=_xlfn.IFS(AH14<2,"<2 Years",AH14<=5, "2-5 Years",AH14<=10,"6-10 Years",AH14>10,"10++ Years")} -> 2-5 Years | AJ14: 2 | AK14: 4 | AL14: 3
A15: 34 | B15: {=_xlfn.IFS(A15<25,"<25",A15<=34,"25-34",A15<=44,"35-44",A15<=54,"45-54",A15>=55,"55++")} -> 25-34 | C15: No | D15: =IF(C15="Yes",1,0) -> 0 | E15: Travel_Rarely | F15: 1346 | G15: Research & Development | H15: 19 | I15: {=_xlfn.IFS(H15<=5,"0-5 km",H15<=10,"6-10 km",H15<=20,"11-20 km",H15>20,"20 km+")} -> 11-20 km | J15: 2 | K15: Medical | L15: 18 | M15: 2 | N15: Male | O15: 93 | P15: 3 | Q15: 1 | R15: Laboratory Technician | S15: 4 | T15: {=_xlfn.IFS(S15=1,"Low",S15=2,"Medium",S15=3,"High",S15=4,"Very High")} -> Very High | U15: Divorced | V15: 2661 | W15: {=_xlfn.IFS(V15<=$AQ$3,"Low",V15<=$AQ$4,"Lower Middle",V15<=$AQ$5,"Upper Middle",V15>$AQ$5,"High")} -> Low | X15: 8758 | Y15: 0 | Z15: No | AA15: 11 | AB15: 3 | AC15: 3 | AD15: 1 | AE15: 3 | AF15: 2 | AG15: 3 | AH15: 2 | AI15: {=_xlfn.IFS(AH15<2,"<2 Years",AH15<=5, "2-5 Years",AH15<=10,"6-10 Years",AH15>10,"10++ Years")} -> 2-5 Years | AJ15: 2 | AK15: 1 | AL15: 2
A16: 28 | B16: {=_xlfn.IFS(A16<25,"<25",A16<=34,"25-34",A16<=44,"35-44",A16<=54,"45-54",A16>=55,"55++")} -> 25-34 | C16: Yes | D16: =IF(C16="Yes",1,0) -> 1 | E16: Travel_Rarely | F16: 103 | G16: Research & Development | H16: 24 | I16: {=_xlfn.IFS(H16<=5,"0-5 km",H16<=10,"6-10 km",H16<=20,"11-20 km",H16>20,"20 km+")} -> 20 km+ | J16: 3 | K16: Life Sciences | L16: 19 | M16: 3 | N16: Male | O16: 50 | P16: 2 | Q16: 1 | R16: Laboratory Technician | S16: 3 | T16: {=_xlfn.IFS(S16=1,"Low",S16=2,"Medium",S16=3,"High",S16=4,"Very High")} -> High | U16: Single | V16: 2028 | W16: {=_xlfn.IFS(V16<=$AQ$3,"Low",V16<=$AQ$4,"Lower Middle",V16<=$AQ$5,"Upper Middle",V16>$AQ$5,"High")} -> Low | X16: 12947 | Y16: 5 | Z16: Yes | AA16: 14 | AB16: 3 | AC16: 2 | AD16: 0 | AE16: 6 | AF16: 4 | AG16: 3 | AH16: 4 | AI16: {=_xlfn.IFS(AH16<2,"<2 Years",AH16<=5, "2-5 Years",AH16<=10,"6-10 Years",AH16>10,"10++ Years")} -> 2-5 Years | AJ16: 2 | AK16: 0 | AL16: 3
A17: 29 | B17: {=_xlfn.IFS(A17<25,"<25",A17<=34,"25-34",A17<=44,"35-44",A17<=54,"45-54",A17>=55,"55++")} -> 25-34 | C17: No | D17: =IF(C17="Yes",1,0) -> 0 | E17: Travel_Rarely | F17: 1389 | G17: Research & Development | H17: 21 | I17: {=_xlfn.IFS(H17<=5,"0-5 km",H17<=10,"6-10 km",H17<=20,"11-20 km",H17>20,"20 km+")} -> 20 km+ | J17: 4 | K17: Life Sciences | L17: 20 | M17: 2 | N17: Female | O17: 51 | P17: 4 | Q17: 3 | R17: Manufacturing Director | S17: 1 | T17: {=_xlfn.IFS(S17=1,"Low",S17=2,"Medium",S17=3,"High",S17=4,"Very High")} -> Low | U17: Divorced | V17: 9980 | W17: {=_xlfn.IFS(V17<=$AQ$3,"Low",V17<=$AQ$4,"Lower Middle",V17<=$AQ$5,"Upper Middle",V17>$AQ$5,"High")} -> High | X17: 10195 | Y17: 1 | Z17: No | AA17: 11 | AB17: 3 | AC17: 3 | AD17: 1 | AE17: 10 | AF17: 1 | AG17: 3 | AH17: 10 | AI17: {=_xlfn.IFS(AH17<2,"<2 Years",AH17<=5, "2-5 Years",AH17<=10,"6-10 Years",AH17>10,"10++ Years")} -> 6-10 Years | AJ17: 9 | AK17: 8 | AL17: 8
... A1471: 34 | B1471: {=_xlfn.IFS(A1471<25,"<25",A1471<=34,"25-34",A1471<=44,"35-44",A1471<=54,"45-54",A1471>=55,"55++")} -> 25-34 | C1471: No | D1471: =IF(C1471="Yes",1,0) -> 0 | E1471: Travel_Rarely | F1471: 628 | G1471: Research & Development | H1471: 8 | I1471: {=_xlfn.IFS(H1471<=5,"0-5 km",H1471<=10,"6-10 km",H1471<=20,"11-20 km",H1471>20,"20 km+")} -> 6-10 km | J1471: 3 | K1471: Medical | L1471: 2068 | M1471: 2 | N1471: Male | O1471: 82 | P1471: 4 | Q1471: 2 | R1471: Laboratory Technician | S1471: 3 | T1471: {=_xlfn.IFS(S1471=1,"Low",S1471=2,"Medium",S1471=3,"High",S1471=4,"Very High")} -> High | U1471: Married | V1471: 4404 | W1471: {=_xlfn.IFS(V1471<=$AQ$3,"Low",V1471<=$AQ$4,"Lower Middle",V1471<=$AQ$5,"Upper Middle",V1471>$AQ$5,"High")} -> Lower Middle | X1471: 10228 | Y1471: 2 | Z1471: No | AA1471: 12 | AB1471: 3 | AC1471: 1 | AD1471: 0 | AE1471: 6 | AF1471: 3 | AG1471: 4 | AH1471: 4 | AI1471: {=_xlfn.IFS(AH1471<2,"<2 Years",AH1471<=5, "2-5 Years",AH1471<=10,"6-10 Years",AH1471>10,"10++ Years")} -> 2-5 Years | AJ1471: 3 | AK1471: 1 | AL1471: 2

Sheet Pivot_Table
A2: Total Employee | B2: =COUNTA(Clean_data!L2:L1471) -> 1470 | D2: Average Monthly Income | E2: =AVERAGE(Clean_data!V2:V1471) -> 6502.9313
A3: Employee Left | B3: =COUNTIF(Clean_data!D2:D1471,1) -> 237 | D3: Average Age | E3: =AVERAGE(Clean_data!A2:A1471) -> 36.92381
A4: Employee Active | B4: =COUNTIF(Clean_data!D2:D1471,0) -> 1233
A5: Attrition Rate | B5: =$B$3/$B$2 -> 0.16122449
A8: Attrition Flag | B8: Count of EmployeeNumber | D8: CategoryAge | E8: Sum of Attrition Flag
A9: 0 | B9: 1233 | D9: 55++ | E9: 0.046413502
A10: 1 | B10: 237 | D10: 45-54 | E10: 0.10548523
A11: Grand Total | B11: 1470 | D11: <25 | E11: 0.16033755
D12: 35-44 | E12: 0.21518987
D13: 25-34 | E13: 0.47257384
A14: Departement | B14: Count of Attrition Flag
A15: Human Resources | B15: 0.042857143 | D15: Income Band | E15: Sum of Attrition Flag
A16: Sales | B16: 0.30340136 | D16: High | E16: 0.16033755
A17: Research & Development | B17: 0.6537415 | D17: Upper Middle | E17: 0.16455696
D18: Lower Middle | E18: 0.21940928
D19: Low | E19: 0.4556962
A21: Job Role | B21: Sum of Attrition Flag
A22: Research Director | B22: 0.0084388186 | D22: Years at Company | E22: Sum of Attrition Flag
A23: Manager | B23: 0.021097046 | D23: 10++ Years | E23: 0.084388186
A24: Healthcare Representative | B24: 0.037974684 | D24: 6-10 Years | E24: 0.23206751
A25: Manufacturing Director | B25: 0.042194093 | D25: <2 Years | E25: 0.3164557
A26: Human Resources | B26: 0.050632911 | D26: 2-5 Years | E26: 0.36708861
A27: Sales Representative | B27: 0.13924051
A28: Research Scientist | B28: 0.19831224 | D28: Job Satisfaction | E28: Sum of Attrition Flag
A29: Sales Executive | B29: 0.24050633 | D29: High | E29: 0.30801688
A30: Laboratory Technician | B30: 0.26160338 | D30: Low | E30: 0.27848101
D31: Medium | E31: 0.19409283
D32: Very High | E32: 0.21940928
A33: Overtime | B33: Sum of Attrition Flag
A34: No | B34: 0.46413502 | D34: Gender | E34: Sum of Attrition Flag
A35: Yes | B35: 0.53586498 | D35: Female | E35: 0.36708861
D36: Male | E36: 0.63291139
A39: Overtime | B39: Sum of Attrition Flag | C39: Count of EmployeeNumber
A40: No | B40: 110 | C40: 1054
A41: Yes | B41: 127 | C41: 416
A45: Overtime Yes | B45: =$B$40/$C$40 -> 0.10436433
A46: Overtime No | B46: =$B$41/$C$41 -> 0.30528846

Sheet High Risk Profile
A2: High Risk Profile
A3: CategoryAge | B3: JobRole | C3: Total Employee | D3: Employee Left | F3: CategoryAge | G3: JobRole | H3: Total Employee | I3: Employee Left | J3: Attrition Rate
A4: <25 | B4: Healthcare Representative | C4: 1 | D4: 0 | F4: <25 | G4: Healthcare Representative | H4: 1 | I4: 0 | J4: =$I4/$H4 -> 0
A5: <25 | B5: Human Resources | C5: 3 | D5: 2 | F5: <25 | G5: Human Resources | H5: 3 | I5: 2 | J5: =$I5/$H5 -> 0.66666667
A6: <25 | B6: Laboratory Technician | C6: 32 | D6: 14 | F6: <25 | G6: Laboratory Technician | H6: 32 | I6: 14 | J6: =$I6/$H6 -> 0.4375
A7: <25 | B7: Manufacturing Director | C7: 4 | D7: 1 | F7: <25 | G7: Manufacturing Director | H7: 4 | I7: 1 | J7: =$I7/$H7 -> 0.25
A8: <25 | B8: Research Scientist | C8: 30 | D8: 7 | F8: <25 | G8: Research Scientist | H8: 30 | I8: 7 | J8: =$I8/$H8 -> 0.23333333
A9: <25 | B9: Sales Executive | C9: 4 | D9: 1 | F9: <25 | G9: Sales Executive | H9: 4 | I9: 1 | J9: =$I9/$H9 -> 0.25
A10: <25 | B10: Sales Representative | C10: 23 | D10: 13 | F10: <25 | G10: Sales Representative | H10: 23 | I10: 13 | J10: =$I10/$H10 -> 0.56521739
A11: 25-34 | B11: Healthcare Representative | C11: 35 | D11: 3 | F11: 25-34 | G11: Healthcare Representative | H11: 35 | I11: 3 | J11: =$I11/$H11 -> 0.085714286
A12: 25-34 | B12: Human Resources | C12: 22 | D12: 8 | F12: 25-34 | G12: Human Resources | H12: 22 | I12: 8 | J12: =$I12/$H12 -> 0.36363636
A13: 25-34 | B13: Laboratory Technician | C13: 107 | D13: 31 | F13: 25-34 | G13: Laboratory Technician | H13: 107 | I13: 31 | J13: =$I13/$H13 -> 0.28971963
A14: 25-34 | B14: Manager | C14: 7 | D14: 1 | F14: 25-34 | G14: Manager | H14: 7 | I14: 1 | J14: =$I14/$H14 -> 0.14285714
A15: 25-34 | B15: Manufacturing Director | C15: 44 | D15: 2 | F15: 25-34 | G15: Manufacturing Director | H15: 44 | I15: 2 | J15: =$I15/$H15 -> 0.045454545
... A45: 55++ | B45: Sales Executive | C45: 12 | D45: 2 | F45: 55++ | G45: Sales Executive | H45: 12 | I45: 2 | J45: =$I45/$H45 -> 0.16666667
A49: CategoryAge | B49: CategoryMonthlyIncome | C49: JobRole | D49: Total Employee | E49: Employee Left | G49: CategoryAge | H49: CategoryMonthlyIncome | I49: JobRole | J49: Total Employee | K49: Employee Left | L49: Attrition Rate | M49: Category Rank | N49: Risk Profile
A50: <25 | B50: Low | C50: Human Resources | D50: 3 | E50: 2 | G50: 25-34 | H50: High | I50: Human Resources | J50: 1 | K50: 1 | L50: =$K50/$J50 -> 1 | M50: =IF( AND(J50>=10,L50>=0.3), "High Risk", IF( AND(J50>=10,L50>=0.15), "Medium Risk", "Low Risk" )) -> Low Risk | N50: =G50&" | "&H50&" | "&I50 -> 25-34 | High | Human Resources
A51: <25 | B51: Low | C51: Laboratory Technician | D51: 21 | E51: 9 | G51: 55++ | H51: Upper Middle | I51: Research Scientist | J51: 1 | K51: 1 | L51: =$K51/$J51 -> 1 | M51: =IF( AND(J51>=10,L51>=0.3), "High Risk", IF( AND(J51>=10,L51>=0.15), "Medium Risk", "Low Risk" )) -> Low Risk | N51: =G51&" | "&H51&" | "&I51 -> 55++ | Upper Middle | Research Scientist
A52: <25 | B52: Low | C52: Research Scientist | D52: 23 | E52: 7 | G52: 55++ | H52: Low | I52: Laboratory Technician | J52: 4 | K52: 3 | L52: =$K52/$J52 -> 0.75 | M52: =IF( AND(J52>=10,L52>=0.3), "High Risk", IF( AND(J52>=10,L52>=0.15), "Medium Risk", "Low Risk" )) -> Low Risk | N52: =G52&" | "&H52&" | "&I52 -> 55++ | Low | Laboratory Technician
A53: <25 | B53: Low | C53: Sales Representative | D53: 21 | E53: 12 | G53: <25 | H53: Low | I53: Human Resources | J53: 3 | K53: 2 | L53: =$K53/$J53 -> 0.66666667 | M53: =IF( AND(J53>=10,L53>=0.3), "High Risk", IF( AND(J53>=10,L53>=0.15), "Medium Risk", "Low Risk" )) -> Low Risk | N53: =G53&" | "&H53&" | "&I53 -> <25 | Low | Human Resources
A54: <25 | B54: Lower Middle | C54: Healthcare Representative | D54: 1 | E54: 0 | G54: 45-54 | H54: Low | I54: Sales Representative | J54: 3 | K54: 2 | L54: =$K54/$J54 -> 0.66666667 | M54: =IF( AND(J54>=10,L54>=0.3), "High Risk", IF( AND(J54>=10,L54>=0.15), "Medium Risk", "Low Risk" )) -> Low Risk | N54: =G54&" | "&H54&" | "&I54 -> 45-54 | Low | Sales Representative
A55: <25 | B55: Lower Middle | C55: Laboratory Technician | D55: 11 | E55: 5 | G55: <25 | H55: Low | I55: Sales Representative | J55: 21 | K55: 12 | L55: =$K55/$J55 -> 0.57142857 | M55: =IF( AND(J55>=10,L55>=0.3), "High Risk", IF( AND(J55>=10,L55>=0.15), "Medium Risk", "Low Risk" )) -> High Risk | N55: =G55&" | "&H55&" | "&I55 -> <25 | Low | Sales Representative
A56: <25 | B56: Lower Middle | C56: Manufacturing Director | D56: 4 | E56: 1 | G56: <25 | H56: Lower Middle | I56: Sales Representative | J56: 2 | K56: 1 | L56: =$K56/$J56 -> 0.5 | M56: =IF( AND(J56>=10,L56>=0.3), "High Risk", IF( AND(J56>=10,L56>=0.15), "Medium Risk", "Low Risk" )) -> Low Risk | N56: =G56&" | "&H56&" | "&I56 -> <25 | Lower Middle | Sales Representative
A57: <25 | B57: Lower Middle | C57: Research Scientist | D57: 7 | E57: 0 | G57: 25-34 | H57: Low | I57: Human Resources | J57: 12 | K57: 6 | L57: =$K57/$J57 -> 0.5 | M57: =IF( AND(J57>=10,L57>=0.3), "High Risk", IF( AND(J57>=10,L57>=0.15), "Medium Risk", "Low Risk" )) -> High Risk | N57: =G57&" | "&H57&" | "&I57 -> 25-34 | Low | Human Resources
A58: <25 | B58: Lower Middle | C58: Sales Executive | D58: 3 | E58: 1 | G58: 35-44 | H58: High | I58: Human Resources | J58: 2 | K58: 1 | L58: =$K58/$J58 -> 0.5 | M58: =IF( AND(J58>=10,L58>=0.3), "High Risk", IF( AND(J58>=10,L58>=0.15), "Medium Risk", "Low Risk" )) -> Low Risk | N58: =G58&" | "&H58&" | "&I58 -> 35-44 | High | Human Resources
A59: <25 | B59: Lower Middle | C59: Sales Representative | D59: 2 | E59: 1 | G59: 35-44 | H59: Lower Middle | I59: Sales Representative | J59: 4 | K59: 2 | L59: =$K59/$J59 -> 0.5 | M59: =IF( AND(J59>=10,L59>=0.3), "High Risk", IF( AND(J59>=10,L59>=0.15), "Medium Risk", "Low Risk" )) -> Low Risk | N59: =G59&" | "&H59&" | "&I59 -> 35-44 | Lower Middle | Sales Representative
A60: <25 | B60: Upper Middle | C60: Sales Executive | D60: 1 | E60: 0 | G60: <25 | H60: Lower Middle | I60: Laboratory Technician | J60: 11 | K60: 5 | L60: =$K60/$J60 -> 0.45454545 | M60: =IF( AND(J60>=10,L60>=0.3), "High Risk", IF( AND(J60>=10,L60>=0.15), "Medium Risk", "Low Risk" )) -> High Risk | N60: =G60&" | "&H60&" | "&I60 -> <25 | Lower Middle | Laboratory Technician
A61: 25-34 | D61: 554 | E61: 112 | G61: <25 | H61: Low | I61: Laboratory Technician | J61: 21 | K61: 9 | L61: =$K61/$J61 -> 0.42857143 | M61: =IF( AND(J61>=10,L61>=0.3), "High Risk", IF( AND(J61>=10,L61>=0.15), "Medium Risk", "Low Risk" )) -> High Risk | N61: =G61&" | "&H61&" | "&I61 -> <25 | Low | Laboratory Technician
A62: 35-44 | D62: 505 | E62: 51 | G62: 25-34 | H62: Low | I62: Sales Representative | J62: 31 | K62: 13 | L62: =$K62/$J62 -> 0.41935484 | M62: =IF( AND(J62>=10,L62>=0.3), "High Risk", IF( AND(J62>=10,L62>=0.15), "Medium Risk", "Low Risk" )) -> High Risk | N62: =G62&" | "&H62&" | "&I62 -> 25-34 | Low | Sales Representative
A63: 45-54 | B63: High | C63: Healthcare Representative | D63: 17 | E63: 1 | G63: 25-34 | H63: Low | I63: Laboratory Technician | J63: 50 | K63: 18 | L63: =$K63/$J63 -> 0.36 | M63: =IF( AND(J63>=10,L63>=0.3), "High Risk", IF( AND(J63>=10,L63>=0.15), "Medium Risk", "Low Risk" )) -> High Risk | N63: =G63&" | "&H63&" | "&I63 -> 25-34 | Low | Laboratory Technician
A64: 45-54 | B64: High | C64: Human Resources | D64: 2 | E64: 0 | G64: <25 | H64: Lower Middle | I64: Sales Executive | J64: 3 | K64: 1 | L64: =$K64/$J64 -> 0.33333333 | M64: =IF( AND(J64>=10,L64>=0.3), "High Risk", IF( AND(J64>=10,L64>=0.15), "Medium Risk", "Low Risk" )) -> Low Risk | N64: =G64&" | "&H64&" | "&I64 -> <25 | Lower Middle | Sales Executive
A65: 45-54 | B65: High | C65: Manager | D65: 47 | E65: 3 | G65: 25-34 | H65: High | I65: Healthcare Representative | J65: 6 | K65: 2 | L65: =$K65/$J65 -> 0.33333333 | M65: =IF( AND(J65>=10,L65>=0.3), "High Risk", IF( AND(J65>=10,L65>=0.15), "Medium Risk", "Low Risk" )) -> Low Risk | N65: =G65&" | "&H65&" | "&I65 -> 25-34 | High | Healthcare Representative
A66: 45-54 | B66: High | C66: Manufacturing Director | D66: 13 | E66: 2 | G66: <25 | H66: Low | I66: Research Scientist | J66: 23 | K66: 7 | L66: =$K66/$J66 -> 0.30434783 | M66: =IF( AND(J66>=10,L66>=0.3), "High Risk", IF( AND(J66>=10,L66>=0.15), "Medium Risk", "Low Risk" )) -> High Risk | N66: =G66&" | "&H66&" | "&I66 -> <25 | Low | Research Scientist
A67: 45-54 | B67: High | C67: Research Director | D67: 34 | E67: 0 | G67: 45-54 | H67: High | I67: Sales Executive | J67: 20 | K67: 6 | L67: =$K67/$J67 -> 0.3 | M67: =IF( AND(J67>=10,L67>=0.3), "High Risk", IF( AND(J67>=10,L67>=0.15), "Medium Risk", "Low Risk" )) -> High Risk | N67: =G67&" | "&H67&" | "&I67 -> 45-54 | High | Sales Executive
A68: 45-54 | B68: High | C68: Research Scientist | D68: 1 | E68: 0 | G68: 25-34 | H68: Lower Middle | I68: Sales Representative | J68: 7 | K68: 2 | L68: =$K68/$J68 -> 0.28571429 | M68: =IF( AND(J68>=10,L68>=0.3), "High Risk", IF( AND(J68>=10,L68>=0.15), "Medium Risk", "Low Risk" )) -> Low Risk | N68: =G68&" | "&H68&" | "&I68 -> 25-34 | Lower Middle | Sales Representative
A69: 45-54 | B69: High | C69: Sales Executive | D69: 20 | E69: 6 | G69: <25 | H69: Lower Middle | I69: Manufacturing Director | J69: 4 | K69: 1 | L69: =$K69/$J69 -> 0.25 | M69: =IF( AND(J69>=10,L69>=0.3), "High Risk", IF( AND(J69>=10,L69>=0.15), "Medium Risk", "Low Risk" )) -> Low Risk | N69: =G69&" | "&H69&" | "&I69 -> <25 | Lower Middle | Manufacturing Director
A70: 45-54 | B70: Low | C70: Human Resources | D70: 1 | E70: 0 | G70: 25-34 | H70: Upper Middle | I70: Laboratory Technician | J70: 8 | K70: 2 | L70: =$K70/$J70 -> 0.25 | M70: =IF( AND(J70>=10,L70>=0.3), "High Risk", IF( AND(J70>=10,L70>=0.15), "Medium Risk", "Low Risk" )) -> Low Risk | N70: =G70&" | "&H70&" | "&I70 -> 25-34 | Upper Middle | Laboratory Technician
A71: 45-54 | B71: Low | C71: Laboratory Technician | D71: 9 | E71: 0 | G71: 45-54 | H71: Upper Middle | I71: Laboratory Technician | J71: 4 | K71: 1 | L71: =$K71/$J71 -> 0.25 | M71: =IF( AND(J71>=10,L71>=0.3), "High Risk", IF( AND(J71>=10,L71>=0.15), "Medium Risk", "Low Risk" )) -> Low Risk | N71: =G71&" | "&H71&" | "&I71 -> 45-54 | Upper Middle | Laboratory Technician
A72: 45-54 | B72: Low | C72: Research Scientist | D72: 8 | E72: 1 | G72: 45-54 | H72: Upper Middle | I72: Sales Executive | J72: 21 | K72: 5 | L72: =$K72/$J72 -> 0.23809524 | M72: =IF( AND(J72>=10,L72>=0.3), "High Risk", IF( AND(J72>=10,L72>=0.15), "Medium Risk", "Low Risk" )) -> Medium Risk | N72: =G72&" | "&H72&" | "&I72 -> 45-54 | Upper Middle | Sales Executive
A73: 45-54 | B73: Low | C73: Sales Representative | D73: 3 | E73: 2 | G73: 25-34 | H73: Low | I73: Research Scientist | J73: 82 | K73: 19 | L73: =$K73/$J73 -> 0.23170732 | M73: =IF( AND(J73>=10,L73>=0.3), "High Risk", IF( AND(J73>=10,L73>=0.15), "Medium Risk", "Low Risk" )) -> Medium Risk | N73: =G73&" | "&H73&" | "&I73 -> 25-34 | Low | Research Scientist
...

Sheet Dashboard

Sheet Insight
